[ERROR] 2019-10-24 10:28:05,671 | /home/umoms/moms-bench/apps/frappe/frappe/utils/scheduler.py:
Site: moms-site2
Exception in Enqueue Events for Site moms-site2
Traceback (most recent call last):
  File "/home/umoms/moms-bench/apps/frappe/frappe/utils/scheduler.py", line 93, in enqueue_events_for_site
    if is_scheduler_disabled():
  File "/home/umoms/moms-bench/apps/frappe/frappe/utils/scheduler.py", line 237, in is_scheduler_disabled
    return not frappe.utils.cint(frappe.db.get_single_value("System Settings", "enable_scheduler"))
  File "/home/umoms/moms-bench/apps/frappe/frappe/database.py", line 642, in get_single_value
    tabSingles where doctype=%s and field=%s""", (doctype, fieldname))
  File "/home/umoms/moms-bench/apps/frappe/frappe/database.py", line 165, in sql
    self.connect()
  File "/home/umoms/moms-bench/apps/frappe/frappe/database.py", line 115, in connect
    charset='utf8mb4', use_unicode = True, conv = conversions, local_infile = self.local_infile)
  File "/home/umoms/moms-bench/env/local/lib/python2.7/site-packages/pymysql/__init__.py", line 94, in Connect
    return Connection(*args, **kwargs)
  File "/home/umoms/moms-bench/env/local/lib/python2.7/site-packages/pymysql/connections.py", line 325, in __init__
    self.connect()
  File "/home/umoms/moms-bench/env/local/lib/python2.7/site-packages/pymysql/connections.py", line 630, in connect
    raise exc
OperationalError: (2003, "Can't connect to MySQL server on u'localhost' ([Errno 111] Connection refused)")

[ERROR] 2019-10-24 10:29:05,861 | /home/umoms/moms-bench/apps/frappe/frappe/utils/scheduler.py:
Site: moms-site1
Exception in Enqueue Events for Site moms-site1
Traceback (most recent call last):
  File "/home/umoms/moms-bench/apps/frappe/frappe/utils/scheduler.py", line 93, in enqueue_events_for_site
    if is_scheduler_disabled():
  File "/home/umoms/moms-bench/apps/frappe/frappe/utils/scheduler.py", line 237, in is_scheduler_disabled
    return not frappe.utils.cint(frappe.db.get_single_value("System Settings", "enable_scheduler"))
  File "/home/umoms/moms-bench/apps/frappe/frappe/database.py", line 642, in get_single_value
    tabSingles where doctype=%s and field=%s""", (doctype, fieldname))
  File "/home/umoms/moms-bench/apps/frappe/frappe/database.py", line 165, in sql
    self.connect()
  File "/home/umoms/moms-bench/apps/frappe/frappe/database.py", line 115, in connect
    charset='utf8mb4', use_unicode = True, conv = conversions, local_infile = self.local_infile)
  File "/home/umoms/moms-bench/env/local/lib/python2.7/site-packages/pymysql/__init__.py", line 94, in Connect
    return Connection(*args, **kwargs)
  File "/home/umoms/moms-bench/env/local/lib/python2.7/site-packages/pymysql/connections.py", line 325, in __init__
    self.connect()
  File "/home/umoms/moms-bench/env/local/lib/python2.7/site-packages/pymysql/connections.py", line 630, in connect
    raise exc
OperationalError: (2003, "Can't connect to MySQL server on u'localhost' ([Errno 111] Connection refused)")

[ERROR] 2019-10-24 10:29:05,866 | /home/umoms/moms-bench/apps/frappe/frappe/utils/scheduler.py:
Site: moms-site2
Exception in Enqueue Events for Site moms-site2
Traceback (most recent call last):
  File "/home/umoms/moms-bench/apps/frappe/frappe/utils/scheduler.py", line 93, in enqueue_events_for_site
    if is_scheduler_disabled():
  File "/home/umoms/moms-bench/apps/frappe/frappe/utils/scheduler.py", line 237, in is_scheduler_disabled
    return not frappe.utils.cint(frappe.db.get_single_value("System Settings", "enable_scheduler"))
  File "/home/umoms/moms-bench/apps/frappe/frappe/database.py", line 642, in get_single_value
    tabSingles where doctype=%s and field=%s""", (doctype, fieldname))
  File "/home/umoms/moms-bench/apps/frappe/frappe/database.py", line 165, in sql
    self.connect()
  File "/home/umoms/moms-bench/apps/frappe/frappe/database.py", line 115, in connect
    charset='utf8mb4', use_unicode = True, conv = conversions, local_infile = self.local_infile)
  File "/home/umoms/moms-bench/env/local/lib/python2.7/site-packages/pymysql/__init__.py", line 94, in Connect
    return Connection(*args, **kwargs)
  File "/home/umoms/moms-bench/env/local/lib/python2.7/site-packages/pymysql/connections.py", line 325, in __init__
    self.connect()
  File "/home/umoms/moms-bench/env/local/lib/python2.7/site-packages/pymysql/connections.py", line 630, in connect
    raise exc
OperationalError: (2003, "Can't connect to MySQL server on u'localhost' ([Errno 111] Connection refused)")

[ERROR] 2019-10-24 10:30:06,769 | /home/umoms/moms-bench/apps/frappe/frappe/utils/scheduler.py:
Site: moms-site1
Exception in Enqueue Events for Site moms-site1
Traceback (most recent call last):
  File "/home/umoms/moms-bench/apps/frappe/frappe/utils/scheduler.py", line 93, in enqueue_events_for_site
    if is_scheduler_disabled():
  File "/home/umoms/moms-bench/apps/frappe/frappe/utils/scheduler.py", line 237, in is_scheduler_disabled
    return not frappe.utils.cint(frappe.db.get_single_value("System Settings", "enable_scheduler"))
  File "/home/umoms/moms-bench/apps/frappe/frappe/database.py", line 642, in get_single_value
    tabSingles where doctype=%s and field=%s""", (doctype, fieldname))
  File "/home/umoms/moms-bench/apps/frappe/frappe/database.py", line 165, in sql
    self.connect()
  File "/home/umoms/moms-bench/apps/frappe/frappe/database.py", line 115, in connect
    charset='utf8mb4', use_unicode = True, conv = conversions, local_infile = self.local_infile)
  File "/home/umoms/moms-bench/env/local/lib/python2.7/site-packages/pymysql/__init__.py", line 94, in Connect
    return Connection(*args, **kwargs)
  File "/home/umoms/moms-bench/env/local/lib/python2.7/site-packages/pymysql/connections.py", line 325, in __init__
    self.connect()
  File "/home/umoms/moms-bench/env/local/lib/python2.7/site-packages/pymysql/connections.py", line 630, in connect
    raise exc
OperationalError: (2003, "Can't connect to MySQL server on u'localhost' ([Errno 111] Connection refused)")

[ERROR] 2019-10-24 10:30:06,771 | /home/umoms/moms-bench/apps/frappe/frappe/utils/scheduler.py:
Site: moms-site2
Exception in Enqueue Events for Site moms-site2
Traceback (most recent call last):
  File "/home/umoms/moms-bench/apps/frappe/frappe/utils/scheduler.py", line 93, in enqueue_events_for_site
    if is_scheduler_disabled():
  File "/home/umoms/moms-bench/apps/frappe/frappe/utils/scheduler.py", line 237, in is_scheduler_disabled
    return not frappe.utils.cint(frappe.db.get_single_value("System Settings", "enable_scheduler"))
  File "/home/umoms/moms-bench/apps/frappe/frappe/database.py", line 642, in get_single_value
    tabSingles where doctype=%s and field=%s""", (doctype, fieldname))
  File "/home/umoms/moms-bench/apps/frappe/frappe/database.py", line 165, in sql
    self.connect()
  File "/home/umoms/moms-bench/apps/frappe/frappe/database.py", line 115, in connect
    charset='utf8mb4', use_unicode = True, conv = conversions, local_infile = self.local_infile)
  File "/home/umoms/moms-bench/env/local/lib/python2.7/site-packages/pymysql/__init__.py", line 94, in Connect
    return Connection(*args, **kwargs)
  File "/home/umoms/moms-bench/env/local/lib/python2.7/site-packages/pymysql/connections.py", line 325, in __init__
    self.connect()
  File "/home/umoms/moms-bench/env/local/lib/python2.7/site-packages/pymysql/connections.py", line 630, in connect
    raise exc
OperationalError: (2003, "Can't connect to MySQL server on u'localhost' ([Errno 111] Connection refused)")

[ERROR] 2019-10-24 10:31:06,946 | /home/umoms/moms-bench/apps/frappe/frappe/utils/scheduler.py:
Site: moms-site1
Exception in Enqueue Events for Site moms-site1
Traceback (most recent call last):
  File "/home/umoms/moms-bench/apps/frappe/frappe/utils/scheduler.py", line 93, in enqueue_events_for_site
    if is_scheduler_disabled():
  File "/home/umoms/moms-bench/apps/frappe/frappe/utils/scheduler.py", line 237, in is_scheduler_disabled
    return not frappe.utils.cint(frappe.db.get_single_value("System Settings", "enable_scheduler"))
  File "/home/umoms/moms-bench/apps/frappe/frappe/database.py", line 642, in get_single_value
    tabSingles where doctype=%s and field=%s""", (doctype, fieldname))
  File "/home/umoms/moms-bench/apps/frappe/frappe/database.py", line 165, in sql
    self.connect()
  File "/home/umoms/moms-bench/apps/frappe/frappe/database.py", line 115, in connect
    charset='utf8mb4', use_unicode = True, conv = conversions, local_infile = self.local_infile)
  File "/home/umoms/moms-bench/env/local/lib/python2.7/site-packages/pymysql/__init__.py", line 94, in Connect
    return Connection(*args, **kwargs)
  File "/home/umoms/moms-bench/env/local/lib/python2.7/site-packages/pymysql/connections.py", line 325, in __init__
    self.connect()
  File "/home/umoms/moms-bench/env/local/lib/python2.7/site-packages/pymysql/connections.py", line 630, in connect
    raise exc
OperationalError: (2003, "Can't connect to MySQL server on u'localhost' ([Errno 111] Connection refused)")

[ERROR] 2019-10-24 10:31:06,951 | /home/umoms/moms-bench/apps/frappe/frappe/utils/scheduler.py:
Site: moms-site2
Exception in Enqueue Events for Site moms-site2
Traceback (most recent call last):
  File "/home/umoms/moms-bench/apps/frappe/frappe/utils/scheduler.py", line 93, in enqueue_events_for_site
    if is_scheduler_disabled():
  File "/home/umoms/moms-bench/apps/frappe/frappe/utils/scheduler.py", line 237, in is_scheduler_disabled
    return not frappe.utils.cint(frappe.db.get_single_value("System Settings", "enable_scheduler"))
  File "/home/umoms/moms-bench/apps/frappe/frappe/database.py", line 642, in get_single_value
    tabSingles where doctype=%s and field=%s""", (doctype, fieldname))
  File "/home/umoms/moms-bench/apps/frappe/frappe/database.py", line 165, in sql
    self.connect()
  File "/home/umoms/moms-bench/apps/frappe/frappe/database.py", line 115, in connect
    charset='utf8mb4', use_unicode = True, conv = conversions, local_infile = self.local_infile)
  File "/home/umoms/moms-bench/env/local/lib/python2.7/site-packages/pymysql/__init__.py", line 94, in Connect
    return Connection(*args, **kwargs)
  File "/home/umoms/moms-bench/env/local/lib/python2.7/site-packages/pymysql/connections.py", line 325, in __init__
    self.connect()
  File "/home/umoms/moms-bench/env/local/lib/python2.7/site-packages/pymysql/connections.py", line 630, in connect
    raise exc
OperationalError: (2003, "Can't connect to MySQL server on u'localhost' ([Errno 111] Connection refused)")

[ERROR] 2019-10-24 10:32:07,161 | /home/umoms/moms-bench/apps/frappe/frappe/utils/scheduler.py:
Site: moms-site1
Exception in Enqueue Events for Site moms-site1
Traceback (most recent call last):
  File "/home/umoms/moms-bench/apps/frappe/frappe/utils/scheduler.py", line 93, in enqueue_events_for_site
    if is_scheduler_disabled():
  File "/home/umoms/moms-bench/apps/frappe/frappe/utils/scheduler.py", line 237, in is_scheduler_disabled
    return not frappe.utils.cint(frappe.db.get_single_value("System Settings", "enable_scheduler"))
  File "/home/umoms/moms-bench/apps/frappe/frappe/database.py", line 642, in get_single_value
    tabSingles where doctype=%s and field=%s""", (doctype, fieldname))
  File "/home/umoms/moms-bench/apps/frappe/frappe/database.py", line 165, in sql
    self.connect()
  File "/home/umoms/moms-bench/apps/frappe/frappe/database.py", line 115, in connect
    charset='utf8mb4', use_unicode = True, conv = conversions, local_infile = self.local_infile)
  File "/home/umoms/moms-bench/env/local/lib/python2.7/site-packages/pymysql/__init__.py", line 94, in Connect
    return Connection(*args, **kwargs)
  File "/home/umoms/moms-bench/env/local/lib/python2.7/site-packages/pymysql/connections.py", line 325, in __init__
    self.connect()
  File "/home/umoms/moms-bench/env/local/lib/python2.7/site-packages/pymysql/connections.py", line 630, in connect
    raise exc
OperationalError: (2003, "Can't connect to MySQL server on u'localhost' ([Errno 111] Connection refused)")

[ERROR] 2019-10-24 10:32:07,166 | /home/umoms/moms-bench/apps/frappe/frappe/utils/scheduler.py:
Site: moms-site2
Exception in Enqueue Events for Site moms-site2
Traceback (most recent call last):
  File "/home/umoms/moms-bench/apps/frappe/frappe/utils/scheduler.py", line 93, in enqueue_events_for_site
    if is_scheduler_disabled():
  File "/home/umoms/moms-bench/apps/frappe/frappe/utils/scheduler.py", line 237, in is_scheduler_disabled
    return not frappe.utils.cint(frappe.db.get_single_value("System Settings", "enable_scheduler"))
  File "/home/umoms/moms-bench/apps/frappe/frappe/database.py", line 642, in get_single_value
    tabSingles where doctype=%s and field=%s""", (doctype, fieldname))
  File "/home/umoms/moms-bench/apps/frappe/frappe/database.py", line 165, in sql
    self.connect()
  File "/home/umoms/moms-bench/apps/frappe/frappe/database.py", line 115, in connect
    charset='utf8mb4', use_unicode = True, conv = conversions, local_infile = self.local_infile)
  File "/home/umoms/moms-bench/env/local/lib/python2.7/site-packages/pymysql/__init__.py", line 94, in Connect
    return Connection(*args, **kwargs)
  File "/home/umoms/moms-bench/env/local/lib/python2.7/site-packages/pymysql/connections.py", line 325, in __init__
    self.connect()
  File "/home/umoms/moms-bench/env/local/lib/python2.7/site-packages/pymysql/connections.py", line 630, in connect
    raise exc
OperationalError: (2003, "Can't connect to MySQL server on u'localhost' ([Errno 111] Connection refused)")

[ERROR] 2019-10-24 10:33:07,358 | /home/umoms/moms-bench/apps/frappe/frappe/utils/scheduler.py:
Site: moms-site1
Exception in Enqueue Events for Site moms-site1
Traceback (most recent call last):
  File "/home/umoms/moms-bench/apps/frappe/frappe/utils/scheduler.py", line 93, in enqueue_events_for_site
    if is_scheduler_disabled():
  File "/home/umoms/moms-bench/apps/frappe/frappe/utils/scheduler.py", line 237, in is_scheduler_disabled
    return not frappe.utils.cint(frappe.db.get_single_value("System Settings", "enable_scheduler"))
  File "/home/umoms/moms-bench/apps/frappe/frappe/database.py", line 642, in get_single_value
    tabSingles where doctype=%s and field=%s""", (doctype, fieldname))
  File "/home/umoms/moms-bench/apps/frappe/frappe/database.py", line 165, in sql
    self.connect()
  File "/home/umoms/moms-bench/apps/frappe/frappe/database.py", line 115, in connect
    charset='utf8mb4', use_unicode = True, conv = conversions, local_infile = self.local_infile)
  File "/home/umoms/moms-bench/env/local/lib/python2.7/site-packages/pymysql/__init__.py", line 94, in Connect
    return Connection(*args, **kwargs)
  File "/home/umoms/moms-bench/env/local/lib/python2.7/site-packages/pymysql/connections.py", line 325, in __init__
    self.connect()
  File "/home/umoms/moms-bench/env/local/lib/python2.7/site-packages/pymysql/connections.py", line 630, in connect
    raise exc
OperationalError: (2003, "Can't connect to MySQL server on u'localhost' ([Errno 111] Connection refused)")

[ERROR] 2019-10-24 10:33:07,363 | /home/umoms/moms-bench/apps/frappe/frappe/utils/scheduler.py:
Site: moms-site2
Exception in Enqueue Events for Site moms-site2
Traceback (most recent call last):
  File "/home/umoms/moms-bench/apps/frappe/frappe/utils/scheduler.py", line 93, in enqueue_events_for_site
    if is_scheduler_disabled():
  File "/home/umoms/moms-bench/apps/frappe/frappe/utils/scheduler.py", line 237, in is_scheduler_disabled
    return not frappe.utils.cint(frappe.db.get_single_value("System Settings", "enable_scheduler"))
  File "/home/umoms/moms-bench/apps/frappe/frappe/database.py", line 642, in get_single_value
    tabSingles where doctype=%s and field=%s""", (doctype, fieldname))
  File "/home/umoms/moms-bench/apps/frappe/frappe/database.py", line 165, in sql
    self.connect()
  File "/home/umoms/moms-bench/apps/frappe/frappe/database.py", line 115, in connect
    charset='utf8mb4', use_unicode = True, conv = conversions, local_infile = self.local_infile)
  File "/home/umoms/moms-bench/env/local/lib/python2.7/site-packages/pymysql/__init__.py", line 94, in Connect
    return Connection(*args, **kwargs)
  File "/home/umoms/moms-bench/env/local/lib/python2.7/site-packages/pymysql/connections.py", line 325, in __init__
    self.connect()
  File "/home/umoms/moms-bench/env/local/lib/python2.7/site-packages/pymysql/connections.py", line 630, in connect
    raise exc
OperationalError: (2003, "Can't connect to MySQL server on u'localhost' ([Errno 111] Connection refused)")

[ERROR] 2019-10-24 10:34:07,544 | /home/umoms/moms-bench/apps/frappe/frappe/utils/scheduler.py:
Site: moms-site1
Exception in Enqueue Events for Site moms-site1
Traceback (most recent call last):
  File "/home/umoms/moms-bench/apps/frappe/frappe/utils/scheduler.py", line 93, in enqueue_events_for_site
    if is_scheduler_disabled():
  File "/home/umoms/moms-bench/apps/frappe/frappe/utils/scheduler.py", line 237, in is_scheduler_disabled
    return not frappe.utils.cint(frappe.db.get_single_value("System Settings", "enable_scheduler"))
  File "/home/umoms/moms-bench/apps/frappe/frappe/database.py", line 642, in get_single_value
    tabSingles where doctype=%s and field=%s""", (doctype, fieldname))
  File "/home/umoms/moms-bench/apps/frappe/frappe/database.py", line 165, in sql
    self.connect()
  File "/home/umoms/moms-bench/apps/frappe/frappe/database.py", line 115, in connect
    charset='utf8mb4', use_unicode = True, conv = conversions, local_infile = self.local_infile)
  File "/home/umoms/moms-bench/env/local/lib/python2.7/site-packages/pymysql/__init__.py", line 94, in Connect
    return Connection(*args, **kwargs)
  File "/home/umoms/moms-bench/env/local/lib/python2.7/site-packages/pymysql/connections.py", line 325, in __init__
    self.connect()
  File "/home/umoms/moms-bench/env/local/lib/python2.7/site-packages/pymysql/connections.py", line 630, in connect
    raise exc
OperationalError: (2003, "Can't connect to MySQL server on u'localhost' ([Errno 111] Connection refused)")

[ERROR] 2019-10-24 10:34:07,549 | /home/umoms/moms-bench/apps/frappe/frappe/utils/scheduler.py:
Site: moms-site2
Exception in Enqueue Events for Site moms-site2
Traceback (most recent call last):
  File "/home/umoms/moms-bench/apps/frappe/frappe/utils/scheduler.py", line 93, in enqueue_events_for_site
    if is_scheduler_disabled():
  File "/home/umoms/moms-bench/apps/frappe/frappe/utils/scheduler.py", line 237, in is_scheduler_disabled
    return not frappe.utils.cint(frappe.db.get_single_value("System Settings", "enable_scheduler"))
  File "/home/umoms/moms-bench/apps/frappe/frappe/database.py", line 642, in get_single_value
    tabSingles where doctype=%s and field=%s""", (doctype, fieldname))
  File "/home/umoms/moms-bench/apps/frappe/frappe/database.py", line 165, in sql
    self.connect()
  File "/home/umoms/moms-bench/apps/frappe/frappe/database.py", line 115, in connect
    charset='utf8mb4', use_unicode = True, conv = conversions, local_infile = self.local_infile)
  File "/home/umoms/moms-bench/env/local/lib/python2.7/site-packages/pymysql/__init__.py", line 94, in Connect
    return Connection(*args, **kwargs)
  File "/home/umoms/moms-bench/env/local/lib/python2.7/site-packages/pymysql/connections.py", line 325, in __init__
    self.connect()
  File "/home/umoms/moms-bench/env/local/lib/python2.7/site-packages/pymysql/connections.py", line 630, in connect
    raise exc
OperationalError: (2003, "Can't connect to MySQL server on u'localhost' ([Errno 111] Connection refused)")

[ERROR] 2019-10-24 10:35:07,748 | /home/umoms/moms-bench/apps/frappe/frappe/utils/scheduler.py:
Site: moms-site1
Exception in Enqueue Events for Site moms-site1
Traceback (most recent call last):
  File "/home/umoms/moms-bench/apps/frappe/frappe/utils/scheduler.py", line 93, in enqueue_events_for_site
    if is_scheduler_disabled():
  File "/home/umoms/moms-bench/apps/frappe/frappe/utils/scheduler.py", line 237, in is_scheduler_disabled
    return not frappe.utils.cint(frappe.db.get_single_value("System Settings", "enable_scheduler"))
  File "/home/umoms/moms-bench/apps/frappe/frappe/database.py", line 642, in get_single_value
    tabSingles where doctype=%s and field=%s""", (doctype, fieldname))
  File "/home/umoms/moms-bench/apps/frappe/frappe/database.py", line 165, in sql
    self.connect()
  File "/home/umoms/moms-bench/apps/frappe/frappe/database.py", line 115, in connect
    charset='utf8mb4', use_unicode = True, conv = conversions, local_infile = self.local_infile)
  File "/home/umoms/moms-bench/env/local/lib/python2.7/site-packages/pymysql/__init__.py", line 94, in Connect
    return Connection(*args, **kwargs)
  File "/home/umoms/moms-bench/env/local/lib/python2.7/site-packages/pymysql/connections.py", line 325, in __init__
    self.connect()
  File "/home/umoms/moms-bench/env/local/lib/python2.7/site-packages/pymysql/connections.py", line 630, in connect
    raise exc
OperationalError: (2003, "Can't connect to MySQL server on u'localhost' ([Errno 111] Connection refused)")

[ERROR] 2019-10-24 10:35:07,753 | /home/umoms/moms-bench/apps/frappe/frappe/utils/scheduler.py:
Site: moms-site2
Exception in Enqueue Events for Site moms-site2
Traceback (most recent call last):
  File "/home/umoms/moms-bench/apps/frappe/frappe/utils/scheduler.py", line 93, in enqueue_events_for_site
    if is_scheduler_disabled():
  File "/home/umoms/moms-bench/apps/frappe/frappe/utils/scheduler.py", line 237, in is_scheduler_disabled
    return not frappe.utils.cint(frappe.db.get_single_value("System Settings", "enable_scheduler"))
  File "/home/umoms/moms-bench/apps/frappe/frappe/database.py", line 642, in get_single_value
    tabSingles where doctype=%s and field=%s""", (doctype, fieldname))
  File "/home/umoms/moms-bench/apps/frappe/frappe/database.py", line 165, in sql
    self.connect()
  File "/home/umoms/moms-bench/apps/frappe/frappe/database.py", line 115, in connect
    charset='utf8mb4', use_unicode = True, conv = conversions, local_infile = self.local_infile)
  File "/home/umoms/moms-bench/env/local/lib/python2.7/site-packages/pymysql/__init__.py", line 94, in Connect
    return Connection(*args, **kwargs)
  File "/home/umoms/moms-bench/env/local/lib/python2.7/site-packages/pymysql/connections.py", line 325, in __init__
    self.connect()
  File "/home/umoms/moms-bench/env/local/lib/python2.7/site-packages/pymysql/connections.py", line 630, in connect
    raise exc
OperationalError: (2003, "Can't connect to MySQL server on u'localhost' ([Errno 111] Connection refused)")

